[2024-11-05 16:50:25,187] LAP197/INFO/locust.main: Run time limit set to 600 seconds
[2024-11-05 16:50:25,188] LAP197/INFO/locust.main: Starting Locust 2.31.6
[2024-11-05 16:50:25,192] LAP197/INFO/locust.runners: Ramping to 5 users at a rate of 3.00 per second
[2024-11-05 16:50:26,197] LAP197/INFO/locust.runners: All users spawned: {"MyUser": 5} (5 total users)
[2024-11-05 16:50:29,226] LAP197/ERROR/locust.user.task: Expecting value: line 1 column 1 (char 0)
Traceback (most recent call last):
  File "C:\Users\Hemanth\AppData\Local\anaconda3\Lib\site-packages\requests\models.py", line 974, in json
    return complexjson.loads(self.text, **kwargs)
           ^^^^^^^^^^^^^^^^^^^^^^^^^^^^^^^^^^^^^^
  File "C:\Users\Hemanth\AppData\Local\anaconda3\Lib\json\__init__.py", line 346, in loads
    return _default_decoder.decode(s)
           ^^^^^^^^^^^^^^^^^^^^^^^^^^
  File "C:\Users\Hemanth\AppData\Local\anaconda3\Lib\json\decoder.py", line 337, in decode
    obj, end = self.raw_decode(s, idx=_w(s, 0).end())
               ^^^^^^^^^^^^^^^^^^^^^^^^^^^^^^^^^^^^^^
  File "C:\Users\Hemanth\AppData\Local\anaconda3\Lib\json\decoder.py", line 355, in raw_decode
    raise JSONDecodeError("Expecting value", s, err.value) from None
json.decoder.JSONDecodeError: Expecting value: line 1 column 1 (char 0)

During handling of the above exception, another exception occurred:

Traceback (most recent call last):
  File "C:\Users\Hemanth\AppData\Local\anaconda3\Lib\site-packages\locust\user\task.py", line 340, in run
    self.execute_next_task()
  File "C:\Users\Hemanth\AppData\Local\anaconda3\Lib\site-packages\locust\user\task.py", line 373, in execute_next_task
    self.execute_task(self._task_queue.popleft())
  File "C:\Users\Hemanth\AppData\Local\anaconda3\Lib\site-packages\locust\user\task.py", line 385, in execute_task
    task(self)
  File "D:\locust\palm\palm_identificationIR.py", line 82, in identification_palm
    resdata = res.json()
              ^^^^^^^^^^
  File "C:\Users\Hemanth\AppData\Local\anaconda3\Lib\site-packages\requests\models.py", line 978, in json
    raise RequestsJSONDecodeError(e.msg, e.doc, e.pos)
requests.exceptions.JSONDecodeError: Expecting value: line 1 column 1 (char 0)

[2024-11-05 16:50:29,240] LAP197/ERROR/locust.user.task: Expecting value: line 1 column 1 (char 0)
Traceback (most recent call last):
  File "C:\Users\Hemanth\AppData\Local\anaconda3\Lib\site-packages\requests\models.py", line 974, in json
    return complexjson.loads(self.text, **kwargs)
           ^^^^^^^^^^^^^^^^^^^^^^^^^^^^^^^^^^^^^^
  File "C:\Users\Hemanth\AppData\Local\anaconda3\Lib\json\__init__.py", line 346, in loads
    return _default_decoder.decode(s)
           ^^^^^^^^^^^^^^^^^^^^^^^^^^
  File "C:\Users\Hemanth\AppData\Local\anaconda3\Lib\json\decoder.py", line 337, in decode
    obj, end = self.raw_decode(s, idx=_w(s, 0).end())
               ^^^^^^^^^^^^^^^^^^^^^^^^^^^^^^^^^^^^^^
  File "C:\Users\Hemanth\AppData\Local\anaconda3\Lib\json\decoder.py", line 355, in raw_decode
    raise JSONDecodeError("Expecting value", s, err.value) from None
json.decoder.JSONDecodeError: Expecting value: line 1 column 1 (char 0)

During handling of the above exception, another exception occurred:

Traceback (most recent call last):
  File "C:\Users\Hemanth\AppData\Local\anaconda3\Lib\site-packages\locust\user\task.py", line 340, in run
    self.execute_next_task()
  File "C:\Users\Hemanth\AppData\Local\anaconda3\Lib\site-packages\locust\user\task.py", line 373, in execute_next_task
    self.execute_task(self._task_queue.popleft())
  File "C:\Users\Hemanth\AppData\Local\anaconda3\Lib\site-packages\locust\user\task.py", line 385, in execute_task
    task(self)
  File "D:\locust\palm\palm_identificationIR.py", line 82, in identification_palm
    resdata = res.json()
              ^^^^^^^^^^
  File "C:\Users\Hemanth\AppData\Local\anaconda3\Lib\site-packages\requests\models.py", line 978, in json
    raise RequestsJSONDecodeError(e.msg, e.doc, e.pos)
requests.exceptions.JSONDecodeError: Expecting value: line 1 column 1 (char 0)

[2024-11-05 16:50:29,243] LAP197/ERROR/locust.user.task: Expecting value: line 1 column 1 (char 0)
Traceback (most recent call last):
  File "C:\Users\Hemanth\AppData\Local\anaconda3\Lib\site-packages\requests\models.py", line 974, in json
    return complexjson.loads(self.text, **kwargs)
           ^^^^^^^^^^^^^^^^^^^^^^^^^^^^^^^^^^^^^^
  File "C:\Users\Hemanth\AppData\Local\anaconda3\Lib\json\__init__.py", line 346, in loads
    return _default_decoder.decode(s)
           ^^^^^^^^^^^^^^^^^^^^^^^^^^
  File "C:\Users\Hemanth\AppData\Local\anaconda3\Lib\json\decoder.py", line 337, in decode
    obj, end = self.raw_decode(s, idx=_w(s, 0).end())
               ^^^^^^^^^^^^^^^^^^^^^^^^^^^^^^^^^^^^^^
  File "C:\Users\Hemanth\AppData\Local\anaconda3\Lib\json\decoder.py", line 355, in raw_decode
    raise JSONDecodeError("Expecting value", s, err.value) from None
json.decoder.JSONDecodeError: Expecting value: line 1 column 1 (char 0)

During handling of the above exception, another exception occurred:

Traceback (most recent call last):
  File "C:\Users\Hemanth\AppData\Local\anaconda3\Lib\site-packages\locust\user\task.py", line 340, in run
    self.execute_next_task()
  File "C:\Users\Hemanth\AppData\Local\anaconda3\Lib\site-packages\locust\user\task.py", line 373, in execute_next_task
    self.execute_task(self._task_queue.popleft())
  File "C:\Users\Hemanth\AppData\Local\anaconda3\Lib\site-packages\locust\user\task.py", line 385, in execute_task
    task(self)
  File "D:\locust\palm\palm_identificationIR.py", line 82, in identification_palm
    resdata = res.json()
              ^^^^^^^^^^
  File "C:\Users\Hemanth\AppData\Local\anaconda3\Lib\site-packages\requests\models.py", line 978, in json
    raise RequestsJSONDecodeError(e.msg, e.doc, e.pos)
requests.exceptions.JSONDecodeError: Expecting value: line 1 column 1 (char 0)

[2024-11-05 16:50:29,248] LAP197/ERROR/locust.user.task: Expecting value: line 1 column 1 (char 0)
Traceback (most recent call last):
  File "C:\Users\Hemanth\AppData\Local\anaconda3\Lib\site-packages\requests\models.py", line 974, in json
    return complexjson.loads(self.text, **kwargs)
           ^^^^^^^^^^^^^^^^^^^^^^^^^^^^^^^^^^^^^^
  File "C:\Users\Hemanth\AppData\Local\anaconda3\Lib\json\__init__.py", line 346, in loads
    return _default_decoder.decode(s)
           ^^^^^^^^^^^^^^^^^^^^^^^^^^
  File "C:\Users\Hemanth\AppData\Local\anaconda3\Lib\json\decoder.py", line 337, in decode
    obj, end = self.raw_decode(s, idx=_w(s, 0).end())
               ^^^^^^^^^^^^^^^^^^^^^^^^^^^^^^^^^^^^^^
  File "C:\Users\Hemanth\AppData\Local\anaconda3\Lib\json\decoder.py", line 355, in raw_decode
    raise JSONDecodeError("Expecting value", s, err.value) from None
json.decoder.JSONDecodeError: Expecting value: line 1 column 1 (char 0)

During handling of the above exception, another exception occurred:

Traceback (most recent call last):
  File "C:\Users\Hemanth\AppData\Local\anaconda3\Lib\site-packages\locust\user\task.py", line 340, in run
    self.execute_next_task()
  File "C:\Users\Hemanth\AppData\Local\anaconda3\Lib\site-packages\locust\user\task.py", line 373, in execute_next_task
    self.execute_task(self._task_queue.popleft())
  File "C:\Users\Hemanth\AppData\Local\anaconda3\Lib\site-packages\locust\user\task.py", line 385, in execute_task
    task(self)
  File "D:\locust\palm\palm_identificationIR.py", line 82, in identification_palm
    resdata = res.json()
              ^^^^^^^^^^
  File "C:\Users\Hemanth\AppData\Local\anaconda3\Lib\site-packages\requests\models.py", line 978, in json
    raise RequestsJSONDecodeError(e.msg, e.doc, e.pos)
requests.exceptions.JSONDecodeError: Expecting value: line 1 column 1 (char 0)

[2024-11-05 16:50:30,436] LAP197/ERROR/locust.user.task: Expecting value: line 1 column 1 (char 0)
Traceback (most recent call last):
  File "C:\Users\Hemanth\AppData\Local\anaconda3\Lib\site-packages\requests\models.py", line 974, in json
    return complexjson.loads(self.text, **kwargs)
           ^^^^^^^^^^^^^^^^^^^^^^^^^^^^^^^^^^^^^^
  File "C:\Users\Hemanth\AppData\Local\anaconda3\Lib\json\__init__.py", line 346, in loads
    return _default_decoder.decode(s)
           ^^^^^^^^^^^^^^^^^^^^^^^^^^
  File "C:\Users\Hemanth\AppData\Local\anaconda3\Lib\json\decoder.py", line 337, in decode
    obj, end = self.raw_decode(s, idx=_w(s, 0).end())
               ^^^^^^^^^^^^^^^^^^^^^^^^^^^^^^^^^^^^^^
  File "C:\Users\Hemanth\AppData\Local\anaconda3\Lib\json\decoder.py", line 355, in raw_decode
    raise JSONDecodeError("Expecting value", s, err.value) from None
json.decoder.JSONDecodeError: Expecting value: line 1 column 1 (char 0)

During handling of the above exception, another exception occurred:

Traceback (most recent call last):
  File "C:\Users\Hemanth\AppData\Local\anaconda3\Lib\site-packages\locust\user\task.py", line 340, in run
    self.execute_next_task()
  File "C:\Users\Hemanth\AppData\Local\anaconda3\Lib\site-packages\locust\user\task.py", line 373, in execute_next_task
    self.execute_task(self._task_queue.popleft())
  File "C:\Users\Hemanth\AppData\Local\anaconda3\Lib\site-packages\locust\user\task.py", line 385, in execute_task
    task(self)
  File "D:\locust\palm\palm_identificationIR.py", line 82, in identification_palm
    resdata = res.json()
              ^^^^^^^^^^
  File "C:\Users\Hemanth\AppData\Local\anaconda3\Lib\site-packages\requests\models.py", line 978, in json
    raise RequestsJSONDecodeError(e.msg, e.doc, e.pos)
requests.exceptions.JSONDecodeError: Expecting value: line 1 column 1 (char 0)

[2024-11-05 16:50:31,746] LAP197/ERROR/locust.user.task: Expecting value: line 1 column 1 (char 0)
Traceback (most recent call last):
  File "C:\Users\Hemanth\AppData\Local\anaconda3\Lib\site-packages\requests\models.py", line 974, in json
    return complexjson.loads(self.text, **kwargs)
           ^^^^^^^^^^^^^^^^^^^^^^^^^^^^^^^^^^^^^^
  File "C:\Users\Hemanth\AppData\Local\anaconda3\Lib\json\__init__.py", line 346, in loads
    return _default_decoder.decode(s)
           ^^^^^^^^^^^^^^^^^^^^^^^^^^
  File "C:\Users\Hemanth\AppData\Local\anaconda3\Lib\json\decoder.py", line 337, in decode
    obj, end = self.raw_decode(s, idx=_w(s, 0).end())
               ^^^^^^^^^^^^^^^^^^^^^^^^^^^^^^^^^^^^^^
  File "C:\Users\Hemanth\AppData\Local\anaconda3\Lib\json\decoder.py", line 355, in raw_decode
    raise JSONDecodeError("Expecting value", s, err.value) from None
json.decoder.JSONDecodeError: Expecting value: line 1 column 1 (char 0)

During handling of the above exception, another exception occurred:

Traceback (most recent call last):
  File "C:\Users\Hemanth\AppData\Local\anaconda3\Lib\site-packages\locust\user\task.py", line 340, in run
    self.execute_next_task()
  File "C:\Users\Hemanth\AppData\Local\anaconda3\Lib\site-packages\locust\user\task.py", line 373, in execute_next_task
    self.execute_task(self._task_queue.popleft())
  File "C:\Users\Hemanth\AppData\Local\anaconda3\Lib\site-packages\locust\user\task.py", line 385, in execute_task
    task(self)
  File "D:\locust\palm\palm_identificationIR.py", line 82, in identification_palm
    resdata = res.json()
              ^^^^^^^^^^
  File "C:\Users\Hemanth\AppData\Local\anaconda3\Lib\site-packages\requests\models.py", line 978, in json
    raise RequestsJSONDecodeError(e.msg, e.doc, e.pos)
requests.exceptions.JSONDecodeError: Expecting value: line 1 column 1 (char 0)

[2024-11-05 16:50:33,183] LAP197/ERROR/locust.user.task: Expecting value: line 1 column 1 (char 0)
Traceback (most recent call last):
  File "C:\Users\Hemanth\AppData\Local\anaconda3\Lib\site-packages\requests\models.py", line 974, in json
    return complexjson.loads(self.text, **kwargs)
           ^^^^^^^^^^^^^^^^^^^^^^^^^^^^^^^^^^^^^^
  File "C:\Users\Hemanth\AppData\Local\anaconda3\Lib\json\__init__.py", line 346, in loads
    return _default_decoder.decode(s)
           ^^^^^^^^^^^^^^^^^^^^^^^^^^
  File "C:\Users\Hemanth\AppData\Local\anaconda3\Lib\json\decoder.py", line 337, in decode
    obj, end = self.raw_decode(s, idx=_w(s, 0).end())
               ^^^^^^^^^^^^^^^^^^^^^^^^^^^^^^^^^^^^^^
  File "C:\Users\Hemanth\AppData\Local\anaconda3\Lib\json\decoder.py", line 355, in raw_decode
    raise JSONDecodeError("Expecting value", s, err.value) from None
json.decoder.JSONDecodeError: Expecting value: line 1 column 1 (char 0)

During handling of the above exception, another exception occurred:

Traceback (most recent call last):
  File "C:\Users\Hemanth\AppData\Local\anaconda3\Lib\site-packages\locust\user\task.py", line 340, in run
    self.execute_next_task()
  File "C:\Users\Hemanth\AppData\Local\anaconda3\Lib\site-packages\locust\user\task.py", line 373, in execute_next_task
    self.execute_task(self._task_queue.popleft())
  File "C:\Users\Hemanth\AppData\Local\anaconda3\Lib\site-packages\locust\user\task.py", line 385, in execute_task
    task(self)
  File "D:\locust\palm\palm_identificationIR.py", line 82, in identification_palm
    resdata = res.json()
              ^^^^^^^^^^
  File "C:\Users\Hemanth\AppData\Local\anaconda3\Lib\site-packages\requests\models.py", line 978, in json
    raise RequestsJSONDecodeError(e.msg, e.doc, e.pos)
requests.exceptions.JSONDecodeError: Expecting value: line 1 column 1 (char 0)

[2024-11-05 16:50:33,371] LAP197/ERROR/locust.user.task: Expecting value: line 1 column 1 (char 0)
Traceback (most recent call last):
  File "C:\Users\Hemanth\AppData\Local\anaconda3\Lib\site-packages\requests\models.py", line 974, in json
    return complexjson.loads(self.text, **kwargs)
           ^^^^^^^^^^^^^^^^^^^^^^^^^^^^^^^^^^^^^^
  File "C:\Users\Hemanth\AppData\Local\anaconda3\Lib\json\__init__.py", line 346, in loads
    return _default_decoder.decode(s)
           ^^^^^^^^^^^^^^^^^^^^^^^^^^
  File "C:\Users\Hemanth\AppData\Local\anaconda3\Lib\json\decoder.py", line 337, in decode
    obj, end = self.raw_decode(s, idx=_w(s, 0).end())
               ^^^^^^^^^^^^^^^^^^^^^^^^^^^^^^^^^^^^^^
  File "C:\Users\Hemanth\AppData\Local\anaconda3\Lib\json\decoder.py", line 355, in raw_decode
    raise JSONDecodeError("Expecting value", s, err.value) from None
json.decoder.JSONDecodeError: Expecting value: line 1 column 1 (char 0)

During handling of the above exception, another exception occurred:

Traceback (most recent call last):
  File "C:\Users\Hemanth\AppData\Local\anaconda3\Lib\site-packages\locust\user\task.py", line 340, in run
    self.execute_next_task()
  File "C:\Users\Hemanth\AppData\Local\anaconda3\Lib\site-packages\locust\user\task.py", line 373, in execute_next_task
    self.execute_task(self._task_queue.popleft())
  File "C:\Users\Hemanth\AppData\Local\anaconda3\Lib\site-packages\locust\user\task.py", line 385, in execute_task
    task(self)
  File "D:\locust\palm\palm_identificationIR.py", line 82, in identification_palm
    resdata = res.json()
              ^^^^^^^^^^
  File "C:\Users\Hemanth\AppData\Local\anaconda3\Lib\site-packages\requests\models.py", line 978, in json
    raise RequestsJSONDecodeError(e.msg, e.doc, e.pos)
requests.exceptions.JSONDecodeError: Expecting value: line 1 column 1 (char 0)

[2024-11-05 16:50:33,486] LAP197/ERROR/locust.user.task: Expecting value: line 1 column 1 (char 0)
Traceback (most recent call last):
  File "C:\Users\Hemanth\AppData\Local\anaconda3\Lib\site-packages\requests\models.py", line 974, in json
    return complexjson.loads(self.text, **kwargs)
           ^^^^^^^^^^^^^^^^^^^^^^^^^^^^^^^^^^^^^^
  File "C:\Users\Hemanth\AppData\Local\anaconda3\Lib\json\__init__.py", line 346, in loads
    return _default_decoder.decode(s)
           ^^^^^^^^^^^^^^^^^^^^^^^^^^
  File "C:\Users\Hemanth\AppData\Local\anaconda3\Lib\json\decoder.py", line 337, in decode
    obj, end = self.raw_decode(s, idx=_w(s, 0).end())
               ^^^^^^^^^^^^^^^^^^^^^^^^^^^^^^^^^^^^^^
  File "C:\Users\Hemanth\AppData\Local\anaconda3\Lib\json\decoder.py", line 355, in raw_decode
    raise JSONDecodeError("Expecting value", s, err.value) from None
json.decoder.JSONDecodeError: Expecting value: line 1 column 1 (char 0)

During handling of the above exception, another exception occurred:

Traceback (most recent call last):
  File "C:\Users\Hemanth\AppData\Local\anaconda3\Lib\site-packages\locust\user\task.py", line 340, in run
    self.execute_next_task()
  File "C:\Users\Hemanth\AppData\Local\anaconda3\Lib\site-packages\locust\user\task.py", line 373, in execute_next_task
    self.execute_task(self._task_queue.popleft())
  File "C:\Users\Hemanth\AppData\Local\anaconda3\Lib\site-packages\locust\user\task.py", line 385, in execute_task
    task(self)
  File "D:\locust\palm\palm_identificationIR.py", line 82, in identification_palm
    resdata = res.json()
              ^^^^^^^^^^
  File "C:\Users\Hemanth\AppData\Local\anaconda3\Lib\site-packages\requests\models.py", line 978, in json
    raise RequestsJSONDecodeError(e.msg, e.doc, e.pos)
requests.exceptions.JSONDecodeError: Expecting value: line 1 column 1 (char 0)

[2024-11-05 16:50:34,474] LAP197/ERROR/locust.user.task: Expecting value: line 1 column 1 (char 0)
Traceback (most recent call last):
  File "C:\Users\Hemanth\AppData\Local\anaconda3\Lib\site-packages\requests\models.py", line 974, in json
    return complexjson.loads(self.text, **kwargs)
           ^^^^^^^^^^^^^^^^^^^^^^^^^^^^^^^^^^^^^^
  File "C:\Users\Hemanth\AppData\Local\anaconda3\Lib\json\__init__.py", line 346, in loads
    return _default_decoder.decode(s)
           ^^^^^^^^^^^^^^^^^^^^^^^^^^
  File "C:\Users\Hemanth\AppData\Local\anaconda3\Lib\json\decoder.py", line 337, in decode
    obj, end = self.raw_decode(s, idx=_w(s, 0).end())
               ^^^^^^^^^^^^^^^^^^^^^^^^^^^^^^^^^^^^^^
  File "C:\Users\Hemanth\AppData\Local\anaconda3\Lib\json\decoder.py", line 355, in raw_decode
    raise JSONDecodeError("Expecting value", s, err.value) from None
json.decoder.JSONDecodeError: Expecting value: line 1 column 1 (char 0)

During handling of the above exception, another exception occurred:

Traceback (most recent call last):
  File "C:\Users\Hemanth\AppData\Local\anaconda3\Lib\site-packages\locust\user\task.py", line 340, in run
    self.execute_next_task()
  File "C:\Users\Hemanth\AppData\Local\anaconda3\Lib\site-packages\locust\user\task.py", line 373, in execute_next_task
    self.execute_task(self._task_queue.popleft())
  File "C:\Users\Hemanth\AppData\Local\anaconda3\Lib\site-packages\locust\user\task.py", line 385, in execute_task
    task(self)
  File "D:\locust\palm\palm_identificationIR.py", line 82, in identification_palm
    resdata = res.json()
              ^^^^^^^^^^
  File "C:\Users\Hemanth\AppData\Local\anaconda3\Lib\site-packages\requests\models.py", line 978, in json
    raise RequestsJSONDecodeError(e.msg, e.doc, e.pos)
requests.exceptions.JSONDecodeError: Expecting value: line 1 column 1 (char 0)

[2024-11-05 16:50:34,572] LAP197/ERROR/locust.user.task: Expecting value: line 1 column 1 (char 0)
Traceback (most recent call last):
  File "C:\Users\Hemanth\AppData\Local\anaconda3\Lib\site-packages\requests\models.py", line 974, in json
    return complexjson.loads(self.text, **kwargs)
           ^^^^^^^^^^^^^^^^^^^^^^^^^^^^^^^^^^^^^^
  File "C:\Users\Hemanth\AppData\Local\anaconda3\Lib\json\__init__.py", line 346, in loads
    return _default_decoder.decode(s)
           ^^^^^^^^^^^^^^^^^^^^^^^^^^
  File "C:\Users\Hemanth\AppData\Local\anaconda3\Lib\json\decoder.py", line 337, in decode
    obj, end = self.raw_decode(s, idx=_w(s, 0).end())
               ^^^^^^^^^^^^^^^^^^^^^^^^^^^^^^^^^^^^^^
  File "C:\Users\Hemanth\AppData\Local\anaconda3\Lib\json\decoder.py", line 355, in raw_decode
    raise JSONDecodeError("Expecting value", s, err.value) from None
json.decoder.JSONDecodeError: Expecting value: line 1 column 1 (char 0)

During handling of the above exception, another exception occurred:

Traceback (most recent call last):
  File "C:\Users\Hemanth\AppData\Local\anaconda3\Lib\site-packages\locust\user\task.py", line 340, in run
    self.execute_next_task()
  File "C:\Users\Hemanth\AppData\Local\anaconda3\Lib\site-packages\locust\user\task.py", line 373, in execute_next_task
    self.execute_task(self._task_queue.popleft())
  File "C:\Users\Hemanth\AppData\Local\anaconda3\Lib\site-packages\locust\user\task.py", line 385, in execute_task
    task(self)
  File "D:\locust\palm\palm_identificationIR.py", line 82, in identification_palm
    resdata = res.json()
              ^^^^^^^^^^
  File "C:\Users\Hemanth\AppData\Local\anaconda3\Lib\site-packages\requests\models.py", line 978, in json
    raise RequestsJSONDecodeError(e.msg, e.doc, e.pos)
requests.exceptions.JSONDecodeError: Expecting value: line 1 column 1 (char 0)

[2024-11-05 16:50:36,042] LAP197/ERROR/locust.user.task: Expecting value: line 1 column 1 (char 0)
Traceback (most recent call last):
  File "C:\Users\Hemanth\AppData\Local\anaconda3\Lib\site-packages\requests\models.py", line 974, in json
    return complexjson.loads(self.text, **kwargs)
           ^^^^^^^^^^^^^^^^^^^^^^^^^^^^^^^^^^^^^^
  File "C:\Users\Hemanth\AppData\Local\anaconda3\Lib\json\__init__.py", line 346, in loads
    return _default_decoder.decode(s)
           ^^^^^^^^^^^^^^^^^^^^^^^^^^
  File "C:\Users\Hemanth\AppData\Local\anaconda3\Lib\json\decoder.py", line 337, in decode
    obj, end = self.raw_decode(s, idx=_w(s, 0).end())
               ^^^^^^^^^^^^^^^^^^^^^^^^^^^^^^^^^^^^^^
  File "C:\Users\Hemanth\AppData\Local\anaconda3\Lib\json\decoder.py", line 355, in raw_decode
    raise JSONDecodeError("Expecting value", s, err.value) from None
json.decoder.JSONDecodeError: Expecting value: line 1 column 1 (char 0)

During handling of the above exception, another exception occurred:

Traceback (most recent call last):
  File "C:\Users\Hemanth\AppData\Local\anaconda3\Lib\site-packages\locust\user\task.py", line 340, in run
    self.execute_next_task()
  File "C:\Users\Hemanth\AppData\Local\anaconda3\Lib\site-packages\locust\user\task.py", line 373, in execute_next_task
    self.execute_task(self._task_queue.popleft())
  File "C:\Users\Hemanth\AppData\Local\anaconda3\Lib\site-packages\locust\user\task.py", line 385, in execute_task
    task(self)
  File "D:\locust\palm\palm_identificationIR.py", line 82, in identification_palm
    resdata = res.json()
              ^^^^^^^^^^
  File "C:\Users\Hemanth\AppData\Local\anaconda3\Lib\site-packages\requests\models.py", line 978, in json
    raise RequestsJSONDecodeError(e.msg, e.doc, e.pos)
requests.exceptions.JSONDecodeError: Expecting value: line 1 column 1 (char 0)

[2024-11-05 16:50:36,297] LAP197/ERROR/locust.user.task: Expecting value: line 1 column 1 (char 0)
Traceback (most recent call last):
  File "C:\Users\Hemanth\AppData\Local\anaconda3\Lib\site-packages\requests\models.py", line 974, in json
    return complexjson.loads(self.text, **kwargs)
           ^^^^^^^^^^^^^^^^^^^^^^^^^^^^^^^^^^^^^^
  File "C:\Users\Hemanth\AppData\Local\anaconda3\Lib\json\__init__.py", line 346, in loads
    return _default_decoder.decode(s)
           ^^^^^^^^^^^^^^^^^^^^^^^^^^
  File "C:\Users\Hemanth\AppData\Local\anaconda3\Lib\json\decoder.py", line 337, in decode
    obj, end = self.raw_decode(s, idx=_w(s, 0).end())
               ^^^^^^^^^^^^^^^^^^^^^^^^^^^^^^^^^^^^^^
  File "C:\Users\Hemanth\AppData\Local\anaconda3\Lib\json\decoder.py", line 355, in raw_decode
    raise JSONDecodeError("Expecting value", s, err.value) from None
json.decoder.JSONDecodeError: Expecting value: line 1 column 1 (char 0)

During handling of the above exception, another exception occurred:

Traceback (most recent call last):
  File "C:\Users\Hemanth\AppData\Local\anaconda3\Lib\site-packages\locust\user\task.py", line 340, in run
    self.execute_next_task()
  File "C:\Users\Hemanth\AppData\Local\anaconda3\Lib\site-packages\locust\user\task.py", line 373, in execute_next_task
    self.execute_task(self._task_queue.popleft())
  File "C:\Users\Hemanth\AppData\Local\anaconda3\Lib\site-packages\locust\user\task.py", line 385, in execute_task
    task(self)
  File "D:\locust\palm\palm_identificationIR.py", line 82, in identification_palm
    resdata = res.json()
              ^^^^^^^^^^
  File "C:\Users\Hemanth\AppData\Local\anaconda3\Lib\site-packages\requests\models.py", line 978, in json
    raise RequestsJSONDecodeError(e.msg, e.doc, e.pos)
requests.exceptions.JSONDecodeError: Expecting value: line 1 column 1 (char 0)

[2024-11-05 16:50:36,992] LAP197/ERROR/locust.user.task: Expecting value: line 1 column 1 (char 0)
Traceback (most recent call last):
  File "C:\Users\Hemanth\AppData\Local\anaconda3\Lib\site-packages\requests\models.py", line 974, in json
    return complexjson.loads(self.text, **kwargs)
           ^^^^^^^^^^^^^^^^^^^^^^^^^^^^^^^^^^^^^^
  File "C:\Users\Hemanth\AppData\Local\anaconda3\Lib\json\__init__.py", line 346, in loads
    return _default_decoder.decode(s)
           ^^^^^^^^^^^^^^^^^^^^^^^^^^
  File "C:\Users\Hemanth\AppData\Local\anaconda3\Lib\json\decoder.py", line 337, in decode
    obj, end = self.raw_decode(s, idx=_w(s, 0).end())
               ^^^^^^^^^^^^^^^^^^^^^^^^^^^^^^^^^^^^^^
  File "C:\Users\Hemanth\AppData\Local\anaconda3\Lib\json\decoder.py", line 355, in raw_decode
    raise JSONDecodeError("Expecting value", s, err.value) from None
json.decoder.JSONDecodeError: Expecting value: line 1 column 1 (char 0)

During handling of the above exception, another exception occurred:

Traceback (most recent call last):
  File "C:\Users\Hemanth\AppData\Local\anaconda3\Lib\site-packages\locust\user\task.py", line 340, in run
    self.execute_next_task()
  File "C:\Users\Hemanth\AppData\Local\anaconda3\Lib\site-packages\locust\user\task.py", line 373, in execute_next_task
    self.execute_task(self._task_queue.popleft())
  File "C:\Users\Hemanth\AppData\Local\anaconda3\Lib\site-packages\locust\user\task.py", line 385, in execute_task
    task(self)
  File "D:\locust\palm\palm_identificationIR.py", line 82, in identification_palm
    resdata = res.json()
              ^^^^^^^^^^
  File "C:\Users\Hemanth\AppData\Local\anaconda3\Lib\site-packages\requests\models.py", line 978, in json
    raise RequestsJSONDecodeError(e.msg, e.doc, e.pos)
requests.exceptions.JSONDecodeError: Expecting value: line 1 column 1 (char 0)

[2024-11-05 16:50:38,890] LAP197/ERROR/locust.user.task: Expecting value: line 1 column 1 (char 0)
Traceback (most recent call last):
  File "C:\Users\Hemanth\AppData\Local\anaconda3\Lib\site-packages\requests\models.py", line 974, in json
    return complexjson.loads(self.text, **kwargs)
           ^^^^^^^^^^^^^^^^^^^^^^^^^^^^^^^^^^^^^^
  File "C:\Users\Hemanth\AppData\Local\anaconda3\Lib\json\__init__.py", line 346, in loads
    return _default_decoder.decode(s)
           ^^^^^^^^^^^^^^^^^^^^^^^^^^
  File "C:\Users\Hemanth\AppData\Local\anaconda3\Lib\json\decoder.py", line 337, in decode
    obj, end = self.raw_decode(s, idx=_w(s, 0).end())
               ^^^^^^^^^^^^^^^^^^^^^^^^^^^^^^^^^^^^^^
  File "C:\Users\Hemanth\AppData\Local\anaconda3\Lib\json\decoder.py", line 355, in raw_decode
    raise JSONDecodeError("Expecting value", s, err.value) from None
json.decoder.JSONDecodeError: Expecting value: line 1 column 1 (char 0)

During handling of the above exception, another exception occurred:

Traceback (most recent call last):
  File "C:\Users\Hemanth\AppData\Local\anaconda3\Lib\site-packages\locust\user\task.py", line 340, in run
    self.execute_next_task()
  File "C:\Users\Hemanth\AppData\Local\anaconda3\Lib\site-packages\locust\user\task.py", line 373, in execute_next_task
    self.execute_task(self._task_queue.popleft())
  File "C:\Users\Hemanth\AppData\Local\anaconda3\Lib\site-packages\locust\user\task.py", line 385, in execute_task
    task(self)
  File "D:\locust\palm\palm_identificationIR.py", line 82, in identification_palm
    resdata = res.json()
              ^^^^^^^^^^
  File "C:\Users\Hemanth\AppData\Local\anaconda3\Lib\site-packages\requests\models.py", line 978, in json
    raise RequestsJSONDecodeError(e.msg, e.doc, e.pos)
requests.exceptions.JSONDecodeError: Expecting value: line 1 column 1 (char 0)

[2024-11-05 16:50:39,180] LAP197/ERROR/locust.user.task: Expecting value: line 1 column 1 (char 0)
Traceback (most recent call last):
  File "C:\Users\Hemanth\AppData\Local\anaconda3\Lib\site-packages\requests\models.py", line 974, in json
    return complexjson.loads(self.text, **kwargs)
           ^^^^^^^^^^^^^^^^^^^^^^^^^^^^^^^^^^^^^^
  File "C:\Users\Hemanth\AppData\Local\anaconda3\Lib\json\__init__.py", line 346, in loads
    return _default_decoder.decode(s)
           ^^^^^^^^^^^^^^^^^^^^^^^^^^
  File "C:\Users\Hemanth\AppData\Local\anaconda3\Lib\json\decoder.py", line 337, in decode
    obj, end = self.raw_decode(s, idx=_w(s, 0).end())
               ^^^^^^^^^^^^^^^^^^^^^^^^^^^^^^^^^^^^^^
  File "C:\Users\Hemanth\AppData\Local\anaconda3\Lib\json\decoder.py", line 355, in raw_decode
    raise JSONDecodeError("Expecting value", s, err.value) from None
json.decoder.JSONDecodeError: Expecting value: line 1 column 1 (char 0)

During handling of the above exception, another exception occurred:

Traceback (most recent call last):
  File "C:\Users\Hemanth\AppData\Local\anaconda3\Lib\site-packages\locust\user\task.py", line 340, in run
    self.execute_next_task()
  File "C:\Users\Hemanth\AppData\Local\anaconda3\Lib\site-packages\locust\user\task.py", line 373, in execute_next_task
    self.execute_task(self._task_queue.popleft())
  File "C:\Users\Hemanth\AppData\Local\anaconda3\Lib\site-packages\locust\user\task.py", line 385, in execute_task
    task(self)
  File "D:\locust\palm\palm_identificationIR.py", line 82, in identification_palm
    resdata = res.json()
              ^^^^^^^^^^
  File "C:\Users\Hemanth\AppData\Local\anaconda3\Lib\site-packages\requests\models.py", line 978, in json
    raise RequestsJSONDecodeError(e.msg, e.doc, e.pos)
requests.exceptions.JSONDecodeError: Expecting value: line 1 column 1 (char 0)

[2024-11-05 16:50:39,662] LAP197/ERROR/locust.user.task: Expecting value: line 1 column 1 (char 0)
Traceback (most recent call last):
  File "C:\Users\Hemanth\AppData\Local\anaconda3\Lib\site-packages\requests\models.py", line 974, in json
    return complexjson.loads(self.text, **kwargs)
           ^^^^^^^^^^^^^^^^^^^^^^^^^^^^^^^^^^^^^^
  File "C:\Users\Hemanth\AppData\Local\anaconda3\Lib\json\__init__.py", line 346, in loads
    return _default_decoder.decode(s)
           ^^^^^^^^^^^^^^^^^^^^^^^^^^
  File "C:\Users\Hemanth\AppData\Local\anaconda3\Lib\json\decoder.py", line 337, in decode
    obj, end = self.raw_decode(s, idx=_w(s, 0).end())
               ^^^^^^^^^^^^^^^^^^^^^^^^^^^^^^^^^^^^^^
  File "C:\Users\Hemanth\AppData\Local\anaconda3\Lib\json\decoder.py", line 355, in raw_decode
    raise JSONDecodeError("Expecting value", s, err.value) from None
json.decoder.JSONDecodeError: Expecting value: line 1 column 1 (char 0)

During handling of the above exception, another exception occurred:

Traceback (most recent call last):
  File "C:\Users\Hemanth\AppData\Local\anaconda3\Lib\site-packages\locust\user\task.py", line 340, in run
    self.execute_next_task()
  File "C:\Users\Hemanth\AppData\Local\anaconda3\Lib\site-packages\locust\user\task.py", line 373, in execute_next_task
    self.execute_task(self._task_queue.popleft())
  File "C:\Users\Hemanth\AppData\Local\anaconda3\Lib\site-packages\locust\user\task.py", line 385, in execute_task
    task(self)
  File "D:\locust\palm\palm_identificationIR.py", line 82, in identification_palm
    resdata = res.json()
              ^^^^^^^^^^
  File "C:\Users\Hemanth\AppData\Local\anaconda3\Lib\site-packages\requests\models.py", line 978, in json
    raise RequestsJSONDecodeError(e.msg, e.doc, e.pos)
requests.exceptions.JSONDecodeError: Expecting value: line 1 column 1 (char 0)

[2024-11-05 16:50:40,857] LAP197/ERROR/locust.user.task: Expecting value: line 1 column 1 (char 0)
Traceback (most recent call last):
  File "C:\Users\Hemanth\AppData\Local\anaconda3\Lib\site-packages\requests\models.py", line 974, in json
    return complexjson.loads(self.text, **kwargs)
           ^^^^^^^^^^^^^^^^^^^^^^^^^^^^^^^^^^^^^^
  File "C:\Users\Hemanth\AppData\Local\anaconda3\Lib\json\__init__.py", line 346, in loads
    return _default_decoder.decode(s)
           ^^^^^^^^^^^^^^^^^^^^^^^^^^
  File "C:\Users\Hemanth\AppData\Local\anaconda3\Lib\json\decoder.py", line 337, in decode
    obj, end = self.raw_decode(s, idx=_w(s, 0).end())
               ^^^^^^^^^^^^^^^^^^^^^^^^^^^^^^^^^^^^^^
  File "C:\Users\Hemanth\AppData\Local\anaconda3\Lib\json\decoder.py", line 355, in raw_decode
    raise JSONDecodeError("Expecting value", s, err.value) from None
json.decoder.JSONDecodeError: Expecting value: line 1 column 1 (char 0)

During handling of the above exception, another exception occurred:

Traceback (most recent call last):
  File "C:\Users\Hemanth\AppData\Local\anaconda3\Lib\site-packages\locust\user\task.py", line 340, in run
    self.execute_next_task()
  File "C:\Users\Hemanth\AppData\Local\anaconda3\Lib\site-packages\locust\user\task.py", line 373, in execute_next_task
    self.execute_task(self._task_queue.popleft())
  File "C:\Users\Hemanth\AppData\Local\anaconda3\Lib\site-packages\locust\user\task.py", line 385, in execute_task
    task(self)
  File "D:\locust\palm\palm_identificationIR.py", line 82, in identification_palm
    resdata = res.json()
              ^^^^^^^^^^
  File "C:\Users\Hemanth\AppData\Local\anaconda3\Lib\site-packages\requests\models.py", line 978, in json
    raise RequestsJSONDecodeError(e.msg, e.doc, e.pos)
requests.exceptions.JSONDecodeError: Expecting value: line 1 column 1 (char 0)

[2024-11-05 16:50:41,322] LAP197/ERROR/locust.user.task: Expecting value: line 1 column 1 (char 0)
Traceback (most recent call last):
  File "C:\Users\Hemanth\AppData\Local\anaconda3\Lib\site-packages\requests\models.py", line 974, in json
    return complexjson.loads(self.text, **kwargs)
           ^^^^^^^^^^^^^^^^^^^^^^^^^^^^^^^^^^^^^^
  File "C:\Users\Hemanth\AppData\Local\anaconda3\Lib\json\__init__.py", line 346, in loads
    return _default_decoder.decode(s)
           ^^^^^^^^^^^^^^^^^^^^^^^^^^
  File "C:\Users\Hemanth\AppData\Local\anaconda3\Lib\json\decoder.py", line 337, in decode
    obj, end = self.raw_decode(s, idx=_w(s, 0).end())
               ^^^^^^^^^^^^^^^^^^^^^^^^^^^^^^^^^^^^^^
  File "C:\Users\Hemanth\AppData\Local\anaconda3\Lib\json\decoder.py", line 355, in raw_decode
    raise JSONDecodeError("Expecting value", s, err.value) from None
json.decoder.JSONDecodeError: Expecting value: line 1 column 1 (char 0)

During handling of the above exception, another exception occurred:

Traceback (most recent call last):
  File "C:\Users\Hemanth\AppData\Local\anaconda3\Lib\site-packages\locust\user\task.py", line 340, in run
    self.execute_next_task()
  File "C:\Users\Hemanth\AppData\Local\anaconda3\Lib\site-packages\locust\user\task.py", line 373, in execute_next_task
    self.execute_task(self._task_queue.popleft())
  File "C:\Users\Hemanth\AppData\Local\anaconda3\Lib\site-packages\locust\user\task.py", line 385, in execute_task
    task(self)
  File "D:\locust\palm\palm_identificationIR.py", line 82, in identification_palm
    resdata = res.json()
              ^^^^^^^^^^
  File "C:\Users\Hemanth\AppData\Local\anaconda3\Lib\site-packages\requests\models.py", line 978, in json
    raise RequestsJSONDecodeError(e.msg, e.doc, e.pos)
requests.exceptions.JSONDecodeError: Expecting value: line 1 column 1 (char 0)

[2024-11-05 16:50:41,446] LAP197/ERROR/locust.user.task: Expecting value: line 1 column 1 (char 0)
Traceback (most recent call last):
  File "C:\Users\Hemanth\AppData\Local\anaconda3\Lib\site-packages\requests\models.py", line 974, in json
    return complexjson.loads(self.text, **kwargs)
           ^^^^^^^^^^^^^^^^^^^^^^^^^^^^^^^^^^^^^^
  File "C:\Users\Hemanth\AppData\Local\anaconda3\Lib\json\__init__.py", line 346, in loads
    return _default_decoder.decode(s)
           ^^^^^^^^^^^^^^^^^^^^^^^^^^
  File "C:\Users\Hemanth\AppData\Local\anaconda3\Lib\json\decoder.py", line 337, in decode
    obj, end = self.raw_decode(s, idx=_w(s, 0).end())
               ^^^^^^^^^^^^^^^^^^^^^^^^^^^^^^^^^^^^^^
  File "C:\Users\Hemanth\AppData\Local\anaconda3\Lib\json\decoder.py", line 355, in raw_decode
    raise JSONDecodeError("Expecting value", s, err.value) from None
json.decoder.JSONDecodeError: Expecting value: line 1 column 1 (char 0)

During handling of the above exception, another exception occurred:

Traceback (most recent call last):
  File "C:\Users\Hemanth\AppData\Local\anaconda3\Lib\site-packages\locust\user\task.py", line 340, in run
    self.execute_next_task()
  File "C:\Users\Hemanth\AppData\Local\anaconda3\Lib\site-packages\locust\user\task.py", line 373, in execute_next_task
    self.execute_task(self._task_queue.popleft())
  File "C:\Users\Hemanth\AppData\Local\anaconda3\Lib\site-packages\locust\user\task.py", line 385, in execute_task
    task(self)
  File "D:\locust\palm\palm_identificationIR.py", line 82, in identification_palm
    resdata = res.json()
              ^^^^^^^^^^
  File "C:\Users\Hemanth\AppData\Local\anaconda3\Lib\site-packages\requests\models.py", line 978, in json
    raise RequestsJSONDecodeError(e.msg, e.doc, e.pos)
requests.exceptions.JSONDecodeError: Expecting value: line 1 column 1 (char 0)

[2024-11-05 16:50:52,735] LAP197/ERROR/locust.user.task: Expecting value: line 1 column 1 (char 0)
Traceback (most recent call last):
  File "C:\Users\Hemanth\AppData\Local\anaconda3\Lib\site-packages\requests\models.py", line 974, in json
    return complexjson.loads(self.text, **kwargs)
           ^^^^^^^^^^^^^^^^^^^^^^^^^^^^^^^^^^^^^^
  File "C:\Users\Hemanth\AppData\Local\anaconda3\Lib\json\__init__.py", line 346, in loads
    return _default_decoder.decode(s)
           ^^^^^^^^^^^^^^^^^^^^^^^^^^
  File "C:\Users\Hemanth\AppData\Local\anaconda3\Lib\json\decoder.py", line 337, in decode
    obj, end = self.raw_decode(s, idx=_w(s, 0).end())
               ^^^^^^^^^^^^^^^^^^^^^^^^^^^^^^^^^^^^^^
  File "C:\Users\Hemanth\AppData\Local\anaconda3\Lib\json\decoder.py", line 355, in raw_decode
    raise JSONDecodeError("Expecting value", s, err.value) from None
json.decoder.JSONDecodeError: Expecting value: line 1 column 1 (char 0)

During handling of the above exception, another exception occurred:

Traceback (most recent call last):
  File "C:\Users\Hemanth\AppData\Local\anaconda3\Lib\site-packages\locust\user\task.py", line 340, in run
    self.execute_next_task()
  File "C:\Users\Hemanth\AppData\Local\anaconda3\Lib\site-packages\locust\user\task.py", line 373, in execute_next_task
    self.execute_task(self._task_queue.popleft())
  File "C:\Users\Hemanth\AppData\Local\anaconda3\Lib\site-packages\locust\user\task.py", line 385, in execute_task
    task(self)
  File "D:\locust\palm\palm_identificationIR.py", line 82, in identification_palm
    resdata = res.json()
              ^^^^^^^^^^
  File "C:\Users\Hemanth\AppData\Local\anaconda3\Lib\site-packages\requests\models.py", line 978, in json
    raise RequestsJSONDecodeError(e.msg, e.doc, e.pos)
requests.exceptions.JSONDecodeError: Expecting value: line 1 column 1 (char 0)

[2024-11-05 16:50:53,153] LAP197/ERROR/locust.user.task: Expecting value: line 1 column 1 (char 0)
Traceback (most recent call last):
  File "C:\Users\Hemanth\AppData\Local\anaconda3\Lib\site-packages\requests\models.py", line 974, in json
    return complexjson.loads(self.text, **kwargs)
           ^^^^^^^^^^^^^^^^^^^^^^^^^^^^^^^^^^^^^^
  File "C:\Users\Hemanth\AppData\Local\anaconda3\Lib\json\__init__.py", line 346, in loads
    return _default_decoder.decode(s)
           ^^^^^^^^^^^^^^^^^^^^^^^^^^
  File "C:\Users\Hemanth\AppData\Local\anaconda3\Lib\json\decoder.py", line 337, in decode
    obj, end = self.raw_decode(s, idx=_w(s, 0).end())
               ^^^^^^^^^^^^^^^^^^^^^^^^^^^^^^^^^^^^^^
  File "C:\Users\Hemanth\AppData\Local\anaconda3\Lib\json\decoder.py", line 355, in raw_decode
    raise JSONDecodeError("Expecting value", s, err.value) from None
json.decoder.JSONDecodeError: Expecting value: line 1 column 1 (char 0)

During handling of the above exception, another exception occurred:

Traceback (most recent call last):
  File "C:\Users\Hemanth\AppData\Local\anaconda3\Lib\site-packages\locust\user\task.py", line 340, in run
    self.execute_next_task()
  File "C:\Users\Hemanth\AppData\Local\anaconda3\Lib\site-packages\locust\user\task.py", line 373, in execute_next_task
    self.execute_task(self._task_queue.popleft())
  File "C:\Users\Hemanth\AppData\Local\anaconda3\Lib\site-packages\locust\user\task.py", line 385, in execute_task
    task(self)
  File "D:\locust\palm\palm_identificationIR.py", line 82, in identification_palm
    resdata = res.json()
              ^^^^^^^^^^
  File "C:\Users\Hemanth\AppData\Local\anaconda3\Lib\site-packages\requests\models.py", line 978, in json
    raise RequestsJSONDecodeError(e.msg, e.doc, e.pos)
requests.exceptions.JSONDecodeError: Expecting value: line 1 column 1 (char 0)

[2024-11-05 16:50:53,457] LAP197/ERROR/locust.user.task: Expecting value: line 1 column 1 (char 0)
Traceback (most recent call last):
  File "C:\Users\Hemanth\AppData\Local\anaconda3\Lib\site-packages\requests\models.py", line 974, in json
    return complexjson.loads(self.text, **kwargs)
           ^^^^^^^^^^^^^^^^^^^^^^^^^^^^^^^^^^^^^^
  File "C:\Users\Hemanth\AppData\Local\anaconda3\Lib\json\__init__.py", line 346, in loads
    return _default_decoder.decode(s)
           ^^^^^^^^^^^^^^^^^^^^^^^^^^
  File "C:\Users\Hemanth\AppData\Local\anaconda3\Lib\json\decoder.py", line 337, in decode
    obj, end = self.raw_decode(s, idx=_w(s, 0).end())
               ^^^^^^^^^^^^^^^^^^^^^^^^^^^^^^^^^^^^^^
  File "C:\Users\Hemanth\AppData\Local\anaconda3\Lib\json\decoder.py", line 355, in raw_decode
    raise JSONDecodeError("Expecting value", s, err.value) from None
json.decoder.JSONDecodeError: Expecting value: line 1 column 1 (char 0)

During handling of the above exception, another exception occurred:

Traceback (most recent call last):
  File "C:\Users\Hemanth\AppData\Local\anaconda3\Lib\site-packages\locust\user\task.py", line 340, in run
    self.execute_next_task()
  File "C:\Users\Hemanth\AppData\Local\anaconda3\Lib\site-packages\locust\user\task.py", line 373, in execute_next_task
    self.execute_task(self._task_queue.popleft())
  File "C:\Users\Hemanth\AppData\Local\anaconda3\Lib\site-packages\locust\user\task.py", line 385, in execute_task
    task(self)
  File "D:\locust\palm\palm_identificationIR.py", line 82, in identification_palm
    resdata = res.json()
              ^^^^^^^^^^
  File "C:\Users\Hemanth\AppData\Local\anaconda3\Lib\site-packages\requests\models.py", line 978, in json
    raise RequestsJSONDecodeError(e.msg, e.doc, e.pos)
requests.exceptions.JSONDecodeError: Expecting value: line 1 column 1 (char 0)

[2024-11-05 16:50:54,412] LAP197/INFO/locust.main: Shutting down (exit code 1)
[2024-11-20 12:20:22,194] LAP197/INFO/locust.main: Run time limit set to 300 seconds
[2024-11-20 12:20:22,195] LAP197/INFO/locust.main: Starting Locust 2.31.6
[2024-11-20 12:20:22,198] LAP197/INFO/locust.runners: Ramping to 5 users at a rate of 1.00 per second
[2024-11-20 12:20:26,231] LAP197/INFO/locust.runners: All users spawned: {"MyUser": 5} (5 total users)
[2024-11-20 12:20:26,847] LAP197/INFO/locust.main: Shutting down (exit code 1)
[2024-11-20 12:21:48,337] LAP197/INFO/locust.main: Run time limit set to 300 seconds
[2024-11-20 12:21:48,338] LAP197/INFO/locust.main: Starting Locust 2.31.6
[2024-11-20 12:21:48,340] LAP197/INFO/locust.runners: Ramping to 5 users at a rate of 1.00 per second
[2024-11-20 12:21:52,368] LAP197/INFO/locust.runners: All users spawned: {"MyUser": 5} (5 total users)
[2024-11-20 12:22:47,982] LAP197/INFO/locust.main: Shutting down (exit code 1)
[2024-11-20 12:23:17,490] LAP197/INFO/locust.main: Run time limit set to 300 seconds
[2024-11-20 12:23:17,491] LAP197/INFO/locust.main: Starting Locust 2.31.6
[2024-11-20 12:23:17,494] LAP197/INFO/locust.runners: Ramping to 5 users at a rate of 1.00 per second
[2024-11-20 12:23:21,517] LAP197/INFO/locust.runners: All users spawned: {"MyUser": 5} (5 total users)
[2024-11-20 12:24:25,453] LAP197/INFO/locust.main: Shutting down (exit code 1)
